timestamp: 2023-12-23T21:16:15.928827
process title: pantsd [/home/david/learning/pants/example1]
sys.argv: ['/home/david/.cache/nce/3d6643e46b53e4cc0b2a0d5c768866226ddce3de1f57f80c4a02d8d39800fa8e/bindings/venvs/2.18.1/bin/pants', '--python-repos-find-links=-[]', 'run', 'src/api/main.py']
pid: 9952
Signal 15 (SIGTERM) was raised. Exiting with failure.
  File "/home/david/.cache/nce/3d6643e46b53e4cc0b2a0d5c768866226ddce3de1f57f80c4a02d8d39800fa8e/bindings/venvs/2.18.1/bin/pants", line 8, in <module>
    sys.exit(main())
  File "/home/david/.cache/nce/3d6643e46b53e4cc0b2a0d5c768866226ddce3de1f57f80c4a02d8d39800fa8e/bindings/venvs/2.18.1/lib/python3.9/site-packages/pants/bin/pants_loader.py", line 112, in main
    PantsLoader.main()
  File "/home/david/.cache/nce/3d6643e46b53e4cc0b2a0d5c768866226ddce3de1f57f80c4a02d8d39800fa8e/bindings/venvs/2.18.1/lib/python3.9/site-packages/pants/bin/pants_loader.py", line 106, in main
    cls.run_alternate_entrypoint(entrypoint)
  File "/home/david/.cache/nce/3d6643e46b53e4cc0b2a0d5c768866226ddce3de1f57f80c4a02d8d39800fa8e/bindings/venvs/2.18.1/lib/python3.9/site-packages/pants/bin/pants_loader.py", line 84, in run_alternate_entrypoint
    entrypoint_fn()
  File "/home/david/.cache/nce/3d6643e46b53e4cc0b2a0d5c768866226ddce3de1f57f80c4a02d8d39800fa8e/bindings/venvs/2.18.1/lib/python3.9/site-packages/pants/pantsd/pants_daemon.py", line 238, in launch_new_pantsd_instance
    daemon.run_sync()
  File "/home/david/.cache/nce/3d6643e46b53e4cc0b2a0d5c768866226ddce3de1f57f80c4a02d8d39800fa8e/bindings/venvs/2.18.1/lib/python3.9/site-packages/pants/pantsd/pants_daemon.py", line 211, in run_sync
    time.sleep(self.JOIN_TIMEOUT_SECONDS)
  File "/home/david/.cache/nce/3d6643e46b53e4cc0b2a0d5c768866226ddce3de1f57f80c4a02d8d39800fa8e/bindings/venvs/2.18.1/lib/python3.9/site-packages/pants/base/exception_sink.py", line 109, in handle_sigterm
    raise self.SignalHandledNonLocalExit(signum, "SIGTERM")
  File "/home/david/.cache/nce/3d6643e46b53e4cc0b2a0d5c768866226ddce3de1f57f80c4a02d8d39800fa8e/bindings/venvs/2.18.1/lib/python3.9/site-packages/pants/base/exception_sink.py", line 94, in __init__
    self.traceback_lines = traceback.format_stack()

